Workbook

Sheet Inventory
A1: SKU | B1: Category | C1: Sub-Category | D1: Niche Tags | E1: Description | F1: Material | G1: Size | H1: Length (mm) | I1: Drive Type | J1: Bulk Qty Ordered | K1: Bulk Cost ($) | L1: Cost Per Piece ($) | M1: Sell Price Each ($) | N1: Markup (x) | O1: Margin (%) | P1: Min Sell Qty | Q1: Reorder Point | R1: Supplier | S1: Notes
A2: SHCS-M2-4 | B2: Screws | C2: Socket Head Cap | D2: 3DP, Drone, Elec | E2: M2 x 4mm Socket Head Cap Screw | F2: SS 18-8 | G2: M2 | H2: 4 | I2: Hex 1.5mm | J2: 500 | K2: 5.5 | L2: =K2/J2 -> 0.011 | M2: 0.08 | N2: =IF(L2>0,M2/L2,"-") -> 7.2727273 | O2: =IF(M2>0,(M2-L2)/M2,"-") -> 0.8625 | P2: 5 | Q2: 50 | R2: Monster Bolts | S2: Camera mounts, micro builds
A3: SHCS-M2-6 | B3: Screws | C3: Socket Head Cap | D3: 3DP, Drone, Elec | E3: M2 x 6mm Socket Head Cap Screw | F3: SS 18-8 | G3: M2 | H3: 6 | I3: Hex 1.5mm | J3: 500 | K3: 5.5 | L3: =K3/J3 -> 0.011 | M3: 0.08 | N3: =IF(L3>0,M3/L3,"-") -> 7.2727273 | O3: =IF(M3>0,(M3-L3)/M3,"-") -> 0.8625 | P3: 5 | Q3: 50 | R3: Monster Bolts | S3: FC/ESC stack mounting
A4: SHCS-M2-8 | B4: Screws | C4: Socket Head Cap | D4: 3DP, Drone, Elec | E4: M2 x 8mm Socket Head Cap Screw | F4: SS 18-8 | G4: M2 | H4: 8 | I4: Hex 1.5mm | J4: 500 | K4: 5.75 | L4: =K4/J4 -> 0.0115 | M4: 0.08 | N4: =IF(L4>0,M4/L4,"-") -> 6.9565217 | O4: =IF(M4>0,(M4-L4)/M4,"-") -> 0.85625 | P4: 5 | Q4: 50 | R4: Monster Bolts | S4: Standoff mounting, cameras
A5: SHCS-M2-10 | B5: Screws | C5: Socket Head Cap | D5: 3DP, Drone, Elec | E5: M2 x 10mm Socket Head Cap Screw | F5: SS 18-8 | G5: M2 | H5: 10 | I5: Hex 1.5mm | J5: 500 | K5: 5.75 | L5: =K5/J5 -> 0.0115 | M5: 0.08 | N5: =IF(L5>0,M5/L5,"-") -> 6.9565217 | O5: =IF(M5>0,(M5-L5)/M5,"-") -> 0.85625 | P5: 5 | Q5: 50 | R5: Monster Bolts
A6: SHCS-M2-12 | B6: Screws | C6: Socket Head Cap | D6: Drone, Elec | E6: M2 x 12mm Socket Head Cap Screw | F6: SS 18-8 | G6: M2 | H6: 12 | I6: Hex 1.5mm | J6: 500 | K6: 6 | L6: =K6/J6 -> 0.012 | M6: 0.08 | N6: =IF(L6>0,M6/L6,"-") -> 6.6666667 | O6: =IF(M6>0,(M6-L6)/M6,"-") -> 0.85 | P6: 5 | Q6: 50 | R6: Monster Bolts | S6: Long camera mount screws
A7: SHCS-M25-6 | B7: Screws | C7: Socket Head Cap | D7: Elec, 3DP | E7: M2.5 x 6mm Socket Head Cap Screw | F7: SS 18-8 | G7: M2.5 | H7: 6 | I7: Hex 2mm | J7: 500 | K7: 5.75 | L7: =K7/J7 -> 0.0115 | M7: 0.08 | N7: =IF(L7>0,M7/L7,"-") -> 6.9565217 | O7: =IF(M7>0,(M7-L7)/M7,"-") -> 0.85625 | P7: 5 | Q7: 50 | R7: Monster Bolts | S7: Raspberry Pi mounting
A8: SHCS-M25-8 | B8: Screws | C8: Socket Head Cap | D8: Elec, 3DP | E8: M2.5 x 8mm Socket Head Cap Screw | F8: SS 18-8 | G8: M2.5 | H8: 8 | I8: Hex 2mm | J8: 500 | K8: 5.75 | L8: =K8/J8 -> 0.0115 | M8: 0.08 | N8: =IF(L8>0,M8/L8,"-") -> 6.9565217 | O8: =IF(M8>0,(M8-L8)/M8,"-") -> 0.85625 | P8: 5 | Q8: 50 | R8: Monster Bolts | S8: Pi + standoff combos
A9: SHCS-M25-10 | B9: Screws | C9: Socket Head Cap | D9: Elec, 3DP | E9: M2.5 x 10mm Socket Head Cap Screw | F9: SS 18-8 | G9: M2.5 | H9: 10 | I9: Hex 2mm | J9: 500 | K9: 6 | L9: =K9/J9 -> 0.012 | M9: 0.08 | N9: =IF(L9>0,M9/L9,"-") -> 6.6666667 | O9: =IF(M9>0,(M9-L9)/M9,"-") -> 0.85 | P9: 5 | Q9: 50 | R9: Monster Bolts
A10: SHCS-M25-12 | B10: Screws | C10: Socket Head Cap | D10: Elec, 3DP | E10: M2.5 x 12mm Socket Head Cap Screw | F10: SS 18-8 | G10: M2.5 | H10: 12 | I10: Hex 2mm | J10: 500 | K10: 6 | L10: =K10/J10 -> 0.012 | M10: 0.08 | N10: =IF(L10>0,M10/L10,"-") -> 6.6666667 | O10: =IF(M10>0,(M10-L10)/M10,"-") -> 0.85 | P10: 5 | Q10: 50 | R10: Monster Bolts
A11: SHCS-M3-6 | B11: Screws | C11: Socket Head Cap | D11: 3DP, Drone | E11: M3 x 6mm Socket Head Cap Screw | F11: SS 18-8 | G11: M3 | H11: 6 | I11: Hex 2.5mm | J11: 1000 | K11: 9.5 | L11: =K11/J11 -> 0.0095 | M11: 0.06 | N11: =IF(L11>0,M11/L11,"-") -> 6.3157895 | O11: =IF(M11>0,(M11-L11)/M11,"-") -> 0.84166667 | P11: 5 | Q11: 100 | R11: Monster Bolts | S11: Voron BOM staple
A12: SHCS-M3-8 | B12: Screws | C12: Socket Head Cap | D12: 3DP, Drone | E12: M3 x 8mm Socket Head Cap Screw | F12: SS 18-8 | G12: M3 | H12: 8 | I12: Hex 2.5mm | J12: 1000 | K12: 9.5 | L12: =K12/J12 -> 0.0095 | M12: 0.06 | N12: =IF(L12>0,M12/L12,"-") -> 6.3157895 | O12: =IF(M12>0,(M12-L12)/M12,"-") -> 0.84166667 | P12: 5 | Q12: 100 | R12: Monster Bolts | S12: Voron most-used size
A13: SHCS-M3-10 | B13: Screws | C13: Socket Head Cap | D13: 3DP, Drone | E13: M3 x 10mm Socket Head Cap Screw | F13: SS 18-8 | G13: M3 | H13: 10 | I13: Hex 2.5mm | J13: 1000 | K13: 9.75 | L13: =K13/J13 -> 0.00975 | M13: 0.06 | N13: =IF(L13>0,M13/L13,"-") -> 6.1538462 | O13: =IF(M13>0,(M13-L13)/M13,"-") -> 0.8375 | P13: 5 | Q13: 100 | R13: Monster Bolts | S13: Frame builds
A14: SHCS-M3-12 | B14: Screws | C14: Socket Head Cap | D14: 3DP, Drone | E14: M3 x 12mm Socket Head Cap Screw | F14: SS 18-8 | G14: M3 | H14: 12 | I14: Hex 2.5mm | J14: 1000 | K14: 10 | L14: =K14/J14 -> 0.01 | M14: 0.07 | N14: =IF(L14>0,M14/L14,"-") -> 7 | O14: =IF(M14>0,(M14-L14)/M14,"-") -> 0.85714286 | P14: 5 | Q14: 100 | R14: Monster Bolts | S14: Voron BOM
A15: SHCS-M3-16 | B15: Screws | C15: Socket Head Cap | D15: 3DP | E15: M3 x 16mm Socket Head Cap Screw | F15: SS 18-8 | G15: M3 | H15: 16 | I15: Hex 2.5mm | J15: 500 | K15: 6 | L15: =K15/J15 -> 0.012 | M15: 0.07 | N15: =IF(L15>0,M15/L15,"-") -> 5.8333333 | O15: =IF(M15>0,(M15-L15)/M15,"-") -> 0.82857143 | P15: 5 | Q15: 50 | R15: Monster Bolts
A16: SHCS-M3-20 | B16: Screws | C16: Socket Head Cap | D16: 3DP | E16: M3 x 20mm Socket Head Cap Screw | F16: SS 18-8 | G16: M3 | H16: 20 | I16: Hex 2.5mm | J16: 500 | K16: 6.5 | L16: =K16/J16 -> 0.013 | M16: 0.08 | N16: =IF(L16>0,M16/L16,"-") -> 6.1538462 | O16: =IF(M16>0,(M16-L16)/M16,"-") -> 0.8375 | P16: 5 | Q16: 50 | R16: Monster Bolts | S16: Voron Z-drive
A17: SHCS-M3-25 | B17: Screws | C17: Socket Head Cap | D17: 3DP | E17: M3 x 25mm Socket Head Cap Screw | F17: SS 18-8 | G17: M3 | H17: 25 | I17: Hex 2.5mm | J17: 500 | K17: 7 | L17: =K17/J17 -> 0.014 | M17: 0.09 | N17: =IF(L17>0,M17/L17,"-") -> 6.4285714 | O17: =IF(M17>0,(M17-L17)/M17,"-") -> 0.84444444 | P17: 5 | Q17: 50 | R17: Monster Bolts
A18: SHCS-M3-30 | B18: Screws | C18: Socket Head Cap | D18: 3DP | E18: M3 x 30mm Socket Head Cap Screw | F18: SS 18-8 | G18: M3 | H18: 30 | I18: Hex 2.5mm | J18: 500 | K18: 7.5 | L18: =K18/J18 -> 0.015 | M18: 0.1 | N18: =IF(L18>0,M18/L18,"-") -> 6.6666667 | O18: =IF(M18>0,(M18-L18)/M18,"-") -> 0.85 | P18: 5 | Q18: 50 | R18: Monster Bolts | S18: Voron BOM
A19: SHCS-M3-35 | B19: Screws | C19: Socket Head Cap | D19: 3DP | E19: M3 x 35mm Socket Head Cap Screw | F19: SS 18-8 | G19: M3 | H19: 35 | I19: Hex 2.5mm | J19: 250 | K19: 4.5 | L19: =K19/J19 -> 0.018 | M19: 0.12 | N19: =IF(L19>0,M19/L19,"-") -> 6.6666667 | O19: =IF(M19>0,(M19-L19)/M19,"-") -> 0.85 | P19: 5 | Q19: 25 | R19: Monster Bolts
A20: SHCS-M3-40 | B20: Screws | C20: Socket Head Cap | D20: 3DP | E20: M3 x 40mm Socket Head Cap Screw | F20: SS 18-8 | G20: M3 | H20: 40 | I20: Hex 2.5mm | J20: 250 | K20: 5 | L20: =K20/J20 -> 0.02 | M20: 0.12 | N20: =IF(L20>0,M20/L20,"-") -> 6 | O20: =IF(M20>0,(M20-L20)/M20,"-") -> 0.83333333 | P20: 5 | Q20: 25 | R20: Monster Bolts | S20: Voron BOM
A21: SHCS-M4-6 | B21: Screws | C21: Socket Head Cap | D21: 3DP | E21: M4 x 6mm Socket Head Cap Screw | F21: SS 18-8 | G21: M4 | H21: 6 | I21: Hex 3mm | J21: 500 | K21: 7.5 | L21: =K21/J21 -> 0.015 | M21: 0.08 | N21: =IF(L21>0,M21/L21,"-") -> 5.3333333 | O21: =IF(M21>0,(M21-L21)/M21,"-") -> 0.8125 | P21: 5 | Q21: 50 | R21: Monster Bolts
A22: SHCS-M4-10 | B22: Screws | C22: Socket Head Cap | D22: 3DP | E22: M4 x 10mm Socket Head Cap Screw | F22: SS 18-8 | G22: M4 | H22: 10 | I22: Hex 3mm | J22: 500 | K22: 8 | L22: =K22/J22 -> 0.016 | M22: 0.08 | N22: =IF(L22>0,M22/L22,"-") -> 5 | O22: =IF(M22>0,(M22-L22)/M22,"-") -> 0.8 | P22: 5 | Q22: 50 | R22: Monster Bolts
A23: SHCS-M4-16 | B23: Screws | C23: Socket Head Cap | D23: 3DP | E23: M4 x 16mm Socket Head Cap Screw | F23: SS 18-8 | G23: M4 | H23: 16 | I23: Hex 3mm | J23: 500 | K23: 8.5 | L23: =K23/J23 -> 0.017 | M23: 0.1 | N23: =IF(L23>0,M23/L23,"-") -> 5.8823529 | O23: =IF(M23>0,(M23-L23)/M23,"-") -> 0.83 | P23: 5 | Q23: 50 | R23: Monster Bolts
A24: SHCS-M5-10 | B24: Screws | C24: Socket Head Cap | D24: 3DP | E24: M5 x 10mm Socket Head Cap Screw | F24: SS 18-8 | G24: M5 | H24: 10 | I24: Hex 4mm | J24: 500 | K24: 9 | L24: =K24/J24 -> 0.018 | M24: 0.1 | N24: =IF(L24>0,M24/L24,"-") -> 5.5555556 | O24: =IF(M24>0,(M24-L24)/M24,"-") -> 0.82 | P24: 5 | Q24: 50 | R24: Monster Bolts | S24: Voron frame assembly
A25: SHCS-M5-16 | B25: Screws | C25: Socket Head Cap | D25: 3DP | E25: M5 x 16mm Socket Head Cap Screw | F25: SS 18-8 | G25: M5 | H25: 16 | I25: Hex 4mm | J25: 500 | K25: 9.5 | L25: =K25/J25 -> 0.019 | M25: 0.12 | N25: =IF(L25>0,M25/L25,"-") -> 6.3157895 | O25: =IF(M25>0,(M25-L25)/M25,"-") -> 0.84166667 | P25: 5 | Q25: 50 | R25: Monster Bolts | S25: Voron BOM (47 needed)
A26: SHCS-M5-25 | B26: Screws | C26: Socket Head Cap | D26: 3DP | E26: M5 x 25mm Socket Head Cap Screw | F26: SS 18-8 | G26: M5 | H26: 25 | I26: Hex 4mm | J26: 250 | K26: 6 | L26: =K26/J26 -> 0.024 | M26: 0.14 | N26: =IF(L26>0,M26/L26,"-") -> 5.8333333 | O26: =IF(M26>0,(M26-L26)/M26,"-") -> 0.82857143 | P26: 5 | Q26: 25 | R26: Monster Bolts
A27: SHCS-M5-30 | B27: Screws | C27: Socket Head Cap | D27: 3DP | E27: M5 x 30mm Socket Head Cap Screw | F27: SS 18-8 | G27: M5 | H27: 30 | I27: Hex 4mm | J27: 250 | K27: 6.5 | L27: =K27/J27 -> 0.026 | M27: 0.15 | N27: =IF(L27>0,M27/L27,"-") -> 5.7692308 | O27: =IF(M27>0,(M27-L27)/M27,"-") -> 0.82666667 | P27: 5 | Q27: 25 | R27: Monster Bolts | S27: Voron BOM (42 needed)
A28: SHCS-M5-40 | B28: Screws | C28: Socket Head Cap | D28: 3DP | E28: M5 x 40mm Socket Head Cap Screw | F28: SS 18-8 | G28: M5 | H28: 40 | I28: Hex 4mm | J28: 250 | K28: 7.5 | L28: =K28/J28 -> 0.03 | M28: 0.18 | N28: =IF(L28>0,M28/L28,"-") -> 6 | O28: =IF(M28>0,(M28-L28)/M28,"-") -> 0.83333333 | P28: 5 | Q28: 25 | R28: Monster Bolts | S28: Voron BOM (22 needed)
A29: BHCS-M3-6 | B29: Screws | C29: Button Head Cap | D29: 3DP, Drone | E29: M3 x 6mm Button Head Cap Screw | F29: SS 18-8 | G29: M3 | H29: 6 | I29: Hex 2mm | J29: 500 | K29: 5.5 | L29: =K29/J29 -> 0.011 | M29: 0.06 | N29: =IF(L29>0,M29/L29,"-") -> 5.4545455 | O29: =IF(M29>0,(M29-L29)/M29,"-") -> 0.81666667 | P29: 5 | Q29: 50 | R29: Albany County | S29: Low profile, Voron BOM (26)
A30: BHCS-M3-8 | B30: Screws | C30: Button Head Cap | D30: 3DP, Drone | E30: M3 x 8mm Button Head Cap Screw | F30: SS 18-8 | G30: M3 | H30: 8 | I30: Hex 2mm | J30: 500 | K30: 5.75 | L30: =K30/J30 -> 0.0115 | M30: 0.07 | N30: =IF(L30>0,M30/L30,"-") -> 6.0869565 | O30: =IF(M30>0,(M30-L30)/M30,"-") -> 0.83571429 | P30: 5 | Q30: 50 | R30: Albany County | S30: Drone frame top plates
A31: BHCS-M3-10 | B31: Screws | C31: Button Head Cap | D31: 3DP, Drone | E31: M3 x 10mm Button Head Cap Screw | F31: SS 18-8 | G31: M3 | H31: 10 | I31: Hex 2mm | J31: 500 | K31: 6 | L31: =K31/J31 -> 0.012 | M31: 0.07 | N31: =IF(L31>0,M31/L31,"-") -> 5.8333333 | O31: =IF(M31>0,(M31-L31)/M31,"-") -> 0.82857143 | P31: 5 | Q31: 50 | R31: Albany County | S31: FPV arm screws
A32: BHCS-M3-12 | B32: Screws | C32: Button Head Cap | D32: 3DP, Drone | E32: M3 x 12mm Button Head Cap Screw | F32: SS 18-8 | G32: M3 | H32: 12 | I32: Hex 2mm | J32: 500 | K32: 6.25 | L32: =K32/J32 -> 0.0125 | M32: 0.08 | N32: =IF(L32>0,M32/L32,"-") -> 6.4 | O32: =IF(M32>0,(M32-L32)/M32,"-") -> 0.84375 | P32: 5 | Q32: 50 | R32: Albany County
A33: BHCS-M3-16 | B33: Screws | C33: Button Head Cap | D33: 3DP | E33: M3 x 16mm Button Head Cap Screw | F33: SS 18-8 | G33: M3 | H33: 16 | I33: Hex 2mm | J33: 250 | K33: 3.75 | L33: =K33/J33 -> 0.015 | M33: 0.09 | N33: =IF(L33>0,M33/L33,"-") -> 6 | O33: =IF(M33>0,(M33-L33)/M33,"-") -> 0.83333333 | P33: 5 | Q33: 25 | R33: Albany County
A34: BHCS-M4-6 | B34: Screws | C34: Button Head Cap | D34: 3DP | E34: M4 x 6mm Button Head Cap Screw | F34: SS 18-8 | G34: M4 | H34: 6 | I34: Hex 2.5mm | J34: 500 | K34: 6.5 | L34: =K34/J34 -> 0.013 | M34: 0.08 | N34: =IF(L34>0,M34/L34,"-") -> 6.1538462 | O34: =IF(M34>0,(M34-L34)/M34,"-") -> 0.8375 | P34: 5 | Q34: 50 | R34: Albany County | S34: Voron BOM (24)
A35: BHCS-M5-10 | B35: Screws | C35: Button Head Cap | D35: 3DP | E35: M5 x 10mm Button Head Cap Screw | F35: SS 18-8 | G35: M5 | H35: 10 | I35: Hex 3mm | J35: 500 | K35: 8 | L35: =K35/J35 -> 0.016 | M35: 0.1 | N35: =IF(L35>0,M35/L35,"-") -> 6.25 | O35: =IF(M35>0,(M35-L35)/M35,"-") -> 0.84 | P35: 5 | Q35: 50 | R35: Albany County | S35: Voron BOM (60)
A36: BHCS-M5-16 | B36: Screws | C36: Button Head Cap | D36: 3DP | E36: M5 x 16mm Button Head Cap Screw | F36: SS 18-8 | G36: M5 | H36: 16 | I36: Hex 3mm | J36: 250 | K36: 5 | L36: =K36/J36 -> 0.02 | M36: 0.12 | N36: =IF(L36>0,M36/L36,"-") -> 6 | O36: =IF(M36>0,(M36-L36)/M36,"-") -> 0.83333333 | P36: 5 | Q36: 25 | R36: Albany County | S36: Voron BOM (47)
A37: CSK-M3-6 | B37: Screws | C37: Countersunk | D37: Drone, 3DP | E37: M3 x 6mm Flat Head Countersunk | F37: SS 18-8 | G37: M3 | H37: 6 | I37: Hex 2mm | J37: 500 | K37: 6 | L37: =K37/J37 -> 0.012 | M37: 0.07 | N37: =IF(L37>0,M37/L37,"-") -> 5.8333333 | O37: =IF(M37>0,(M37-L37)/M37,"-") -> 0.82857143 | P37: 5 | Q37: 50 | R37: Monster Bolts | S37: Flush mount on drone frames
A38: CSK-M3-8 | B38: Screws | C38: Countersunk | D38: Drone, 3DP | E38: M3 x 8mm Flat Head Countersunk | F38: SS 18-8 | G38: M3 | H38: 8 | I38: Hex 2mm | J38: 500 | K38: 6.25 | L38: =K38/J38 -> 0.0125 | M38: 0.07 | N38: =IF(L38>0,M38/L38,"-") -> 5.6 | O38: =IF(M38>0,(M38-L38)/M38,"-") -> 0.82142857 | P38: 5 | Q38: 50 | R38: Monster Bolts | S38: FPV motor mounting
A39: CSK-M3-10 | B39: Screws | C39: Countersunk | D39: Drone | E39: M3 x 10mm Flat Head Countersunk | F39: SS 18-8 | G39: M3 | H39: 10 | I39: Hex 2mm | J39: 500 | K39: 6.5 | L39: =K39/J39 -> 0.013 | M39: 0.08 | N39: =IF(L39>0,M39/L39,"-") -> 6.1538462 | O39: =IF(M39>0,(M39-L39)/M39,"-") -> 0.8375 | P39: 5 | Q39: 50 | R39: Monster Bolts | S39: Motor mount, longer
A40: CSK-M3-12 | B40: Screws | C40: Countersunk | D40: Drone | E40: M3 x 12mm Flat Head Countersunk | F40: SS 18-8 | G40: M3 | H40: 12 | I40: Hex 2mm | J40: 250 | K40: 3.75 | L40: =K40/J40 -> 0.015 | M40: 0.09 | N40: =IF(L40>0,M40/L40,"-") -> 6 | O40: =IF(M40>0,(M40-L40)/M40,"-") -> 0.83333333 | P40: 5 | Q40: 25 | R40: Monster Bolts
...

Sheet Startup Costs
A1: Item | B1: Category | C1: Est. Cost ($) | D1: Notes
A2: Inventory: Screws (SHCS + BHCS + CSK + misc) | B2: Inventory | C2: =SUM(Inventory!K2:K28,Inventory!K29:K42) -> 268.5 | D2: Pulled from Inventory sheet
A3: Inventory: Nuts (hex, nyloc, T-nuts, press) | B3: Inventory | C3: =SUM(Inventory!K43:K56) -> 82.25 | D3: Pulled from Inventory sheet
A4: Inventory: Washers & Shims | B4: Inventory | C4: =SUM(Inventory!K57:K64) -> 29.5 | D4: Pulled from Inventory sheet
A5: Inventory: Heat-Set Inserts | B5: Inventory | C5: =SUM(Inventory!K65:K69) -> 35.5 | D5: Pulled from Inventory sheet
A6: Inventory: Standoffs (metal + nylon) | B6: Inventory | C6: =SUM(Inventory!K70:K81) -> 50 | D6: Pulled from Inventory sheet
A7: Inventory: Nylon hardware | B7: Inventory | C7: =SUM(Inventory!K82:K86) -> 13.25 | D7: Pulled from Inventory sheet
A8: Inventory: Misc (set screws, thumbs, pins, springs) | B8: Inventory | C8: =SUM(Inventory!K87:K95) -> 32.5 | D8: Pulled from Inventory sheet
A9: Small parts organizer bins (Akro-Mils style) | B9: Equipment | C9: 95 | D9: Fits 100+ SKUs
A10: Label maker + labels | B10: Equipment | C10: 30 | D10: Brother P-Touch or similar
A11: Postal scale (USB) | B11: Equipment | C11: 25 | D11: Accurate to 0.1 oz
A12: Poly bags (1000 assorted) | B12: Supplies | C12: 25 | D12: 2x3, 3x5, 4x6 sizes
A13: Bubble mailers (200) | B13: Supplies | C13: 35 | D13: #000 and #00 sizes
A14: Thermal label printer | B14: Equipment | C14: 80 | D14: Shipping labels - optional, can print at home
A15: Domain name (.com) | B15: Website | C15: 12 | D15: Annual cost
A16: Business license | B16: Legal | C16: 75 | D16: Varies by state/county
A17: TOTAL STARTUP COST | C17: =SUM(C2:C16) -> 888.5

Sheet Kit Builder
A1: Kit Name | B1: Component SKU | C1: Qty | D1: Unit Cost ($) | E1: Line Cost ($) | F1: Suggested Price ($) | G1: Kit Margin ($) | H1: Kit Margin (%)
A2: Voron 2.4 Essentials Kit | B2: SHCS-M3-8 | C2: 50 | D2: =IFERROR(VLOOKUP(B2,Inventory!A:L,12,FALSE()),"-") -> 0.0095 | E2: =IF(ISNUMBER(D2),C2*D2,0) -> 0.475
B3: SHCS-M3-12 | C3: 20 | D3: =IFERROR(VLOOKUP(B3,Inventory!A:L,12,FALSE()),"-") -> 0.01 | E3: =IF(ISNUMBER(D3),C3*D3,0) -> 0.2
B4: SHCS-M3-20 | C4: 15 | D4: =IFERROR(VLOOKUP(B4,Inventory!A:L,12,FALSE()),"-") -> 0.013 | E4: =IF(ISNUMBER(D4),C4*D4,0) -> 0.195
B5: SHCS-M3-30 | C5: 10 | D5: =IFERROR(VLOOKUP(B5,Inventory!A:L,12,FALSE()),"-") -> 0.015 | E5: =IF(ISNUMBER(D5),C5*D5,0) -> 0.15
B6: SHCS-M5-16 | C6: 25 | D6: =IFERROR(VLOOKUP(B6,Inventory!A:L,12,FALSE()),"-") -> 0.019 | E6: =IF(ISNUMBER(D6),C6*D6,0) -> 0.475
B7: SHCS-M5-30 | C7: 20 | D7: =IFERROR(VLOOKUP(B7,Inventory!A:L,12,FALSE()),"-") -> 0.026 | E7: =IF(ISNUMBER(D7),C7*D7,0) -> 0.52
B8: BHCS-M3-6 | C8: 15 | D8: =IFERROR(VLOOKUP(B8,Inventory!A:L,12,FALSE()),"-") -> 0.011 | E8: =IF(ISNUMBER(D8),C8*D8,0) -> 0.165
B9: BHCS-M5-10 | C9: 30 | D9: =IFERROR(VLOOKUP(B9,Inventory!A:L,12,FALSE()),"-") -> 0.016 | E9: =IF(ISNUMBER(D9),C9*D9,0) -> 0.48
B10: NUT-M3 | C10: 30 | D10: =IFERROR(VLOOKUP(B10,Inventory!A:L,12,FALSE()),"-") -> 0.005 | E10: =IF(ISNUMBER(D10),C10*D10,0) -> 0.15
B11: NUT-M5 | C11: 25 | D11: =IFERROR(VLOOKUP(B11,Inventory!A:L,12,FALSE()),"-") -> 0.008 | E11: =IF(ISNUMBER(D11),C11*D11,0) -> 0.2
B12: TNUT-M3-ROLL | C12: 50 | D12: =IFERROR(VLOOKUP(B12,Inventory!A:L,12,FALSE()),"-") -> 0.024 | E12: =IF(ISNUMBER(D12),C12*D12,0) -> 1.2
B13: TNUT-M5-ROLL | C13: 40 | D13: =IFERROR(VLOOKUP(B13,Inventory!A:L,12,FALSE()),"-") -> 0.028 | E13: =IF(ISNUMBER(D13),C13*D13,0) -> 1.12
B14: HSI-M3-5x4 | C14: 50 | D14: =IFERROR(VLOOKUP(B14,Inventory!A:L,12,FALSE()),"-") -> 0.012 | E14: =IF(ISNUMBER(D14),C14*D14,0) -> 0.6
B15: WASH-M3 | C15: 20 | D15: =IFERROR(VLOOKUP(B15,Inventory!A:L,12,FALSE()),"-") -> 0.004 | E15: =IF(ISNUMBER(D15),C15*D15,0) -> 0.08
A16: VORON KIT TOTAL | E16: =SUM(E2:E15) -> 6.01 | F16: 39.95 | G16: =F16-E16 -> 33.94 | H16: =IF(F16>0,G16/F16,"-") -> 0.84956195
A18: FPV 5" Quad Hardware Kit | B18: SHCS-M2-6 | C18: 8 | D18: =IFERROR(VLOOKUP(B18,Inventory!A:L,12,FALSE()),"-") -> 0.011 | E18: =IF(ISNUMBER(D18),C18*D18,0) -> 0.088
B19: SHCS-M2-8 | C19: 4 | D19: =IFERROR(VLOOKUP(B19,Inventory!A:L,12,FALSE()),"-") -> 0.0115 | E19: =IF(ISNUMBER(D19),C19*D19,0) -> 0.046
B20: SHCS-M3-8 | C20: 8 | D20: =IFERROR(VLOOKUP(B20,Inventory!A:L,12,FALSE()),"-") -> 0.0095 | E20: =IF(ISNUMBER(D20),C20*D20,0) -> 0.076
B21: BHCS-M3-8 | C21: 8 | D21: =IFERROR(VLOOKUP(B21,Inventory!A:L,12,FALSE()),"-") -> 0.0115 | E21: =IF(ISNUMBER(D21),C21*D21,0) -> 0.092
B22: CSK-M3-8 | C22: 16 | D22: =IFERROR(VLOOKUP(B22,Inventory!A:L,12,FALSE()),"-") -> 0.0125 | E22: =IF(ISNUMBER(D22),C22*D22,0) -> 0.2
B23: NUT-M3 | C23: 8 | D23: =IFERROR(VLOOKUP(B23,Inventory!A:L,12,FALSE()),"-") -> 0.005 | E23: =IF(ISNUMBER(D23),C23*D23,0) -> 0.04
B24: NYLOC-M3 | C24: 8 | D24: =IFERROR(VLOOKUP(B24,Inventory!A:L,12,FALSE()),"-") -> 0.009 | E24: =IF(ISNUMBER(D24),C24*D24,0) -> 0.072
B25: STD-M3-20-FF | C25: 4 | D25: =IFERROR(VLOOKUP(B25,Inventory!A:L,12,FALSE()),"-") -> 0.03 | E25: =IF(ISNUMBER(D25),C25*D25,0) -> 0.12
B26: STD-M3-25-FF | C26: 4 | D26: =IFERROR(VLOOKUP(B26,Inventory!A:L,12,FALSE()),"-") -> 0.0325 | E26: =IF(ISNUMBER(D26),C26*D26,0) -> 0.13
B27: PRESS-M3 | C27: 8 | D27: =IFERROR(VLOOKUP(B27,Inventory!A:L,12,FALSE()),"-") -> 0.03 | E27: =IF(ISNUMBER(D27),C27*D27,0) -> 0.24
A28: FPV KIT TOTAL | E28: =SUM(E18:E27) -> 1.104 | F28: 14.95 | G28: =F28-E28 -> 13.846 | H28: =IF(F28>0,G28/F28,"-") -> 0.92615385
A30: Raspberry Pi Mounting Kit | B30: SHCS-M25-6 | C30: 4 | D30: =IFERROR(VLOOKUP(B30,Inventory!A:L,12,FALSE()),"-") -> 0.0115 | E30: =IF(ISNUMBER(D30),C30*D30,0) -> 0.046
B31: NUT-M25 | C31: 4 | D31: =IFERROR(VLOOKUP(B31,Inventory!A:L,12,FALSE()),"-") -> 0.007 | E31: =IF(ISNUMBER(D31),C31*D31,0) -> 0.028
B32: STD-M25-6-MF | C32: 4 | D32: =IFERROR(VLOOKUP(B32,Inventory!A:L,12,FALSE()),"-") -> 0.025 | E32: =IF(ISNUMBER(D32),C32*D32,0) -> 0.1
B33: WASH-M25 | C33: 4 | D33: =IFERROR(VLOOKUP(B33,Inventory!A:L,12,FALSE()),"-") -> 0.005 | E33: =IF(ISNUMBER(D33),C33*D33,0) -> 0.02
A34: PI KIT TOTAL | E34: =SUM(E30:E33) -> 0.194 | F34: 4.95 | G34: =F34-E34 -> 4.756 | H34: =IF(F34>0,G34/F34,"-") -> 0.96080808
A36: Arduino / PCB Mounting Kit | B36: NSTD-M3-6-MF | C36: 4 | D36: =IFERROR(VLOOKUP(B36,Inventory!A:L,12,FALSE()),"-") -> 0.015 | E36: =IF(ISNUMBER(D36),C36*D36,0) -> 0.06
B37: NSCR-M3-6 | C37: 4 | D37: =IFERROR(VLOOKUP(B37,Inventory!A:L,12,FALSE()),"-") -> 0.01 | E37: =IF(ISNUMBER(D37),C37*D37,0) -> 0.04
B38: NNUT-M3 | C38: 4 | D38: =IFERROR(VLOOKUP(B38,Inventory!A:L,12,FALSE()),"-") -> 0.0075 | E38: =IF(ISNUMBER(D38),C38*D38,0) -> 0.03
B39: WASH-M3 | C39: 4 | D39: =IFERROR(VLOOKUP(B39,Inventory!A:L,12,FALSE()),"-") -> 0.004 | E39: =IF(ISNUMBER(D39),C39*D39,0) -> 0.016
A40: ARDUINO KIT TOTAL | E40: =SUM(E36:E39) -> 0.146 | F40: 3.95 | G40: =F40-E40 -> 3.804 | H40: =IF(F40>0,G40/F40,"-") -> 0.96303797

Sheet Suppliers
A1: Supplier | B1: Website | C1: Min Order | D1: Ship Time | E1: Notes
A2: Monster Bolts | B2: monsterbolts.com | C2: $200 bulk | D2: 3-5 days | E2: Best bulk pricing on metric SHCS. Domestic.
A3: Albany County Fasteners | B3: albanycountyfasteners.com | C3: No minimum | D3: 3-5 days | E3: Good per-piece pricing for button head, standoffs. Domestic.
A4: Bolt Depot | B4: boltdepot.com | C4: No minimum | D4: 2-4 days | E4: Competitor, but useful for fill-in orders of sizes you don't stock.
A5: CNC Kitchen / Vector3D | B5: cnckitchen.store / vector3d.shop | C5: No minimum | D5: 5-10 days | E5: Heat-set inserts. CNC Kitchen = gold standard brand.
A6: Pyrodrone / RaceDayQuads | B6: pyrodrone.com / racedayquads.com | C6: No minimum | D6: 3-5 days | E6: Press nuts, drone-specific hardware. Higher per-piece cost.
A7: AliExpress (various) | B7: aliexpress.com | C7: Usually 100+ | D7: 14-30 days | E7: T-nuts, nylon standoffs, springs. TEST QUALITY before stocking.
A8: McMaster-Carr | B8: mcmaster.com | C8: No minimum | D8: 1-2 days | E8: Emergency restocking only. Price too high for bulk.
